Workbook

Sheet README
A1: 시향노트 향수 데이터 시트 (AI 초안)
A3: ■ 이 파일의 상태
A4: - 향수 50개의 브랜드·이름·노트·분류·한국어 문구를 AI가 초안으로 채웠습니다. 노트와 농도는 AI의 기억에 의존한 값이라 틀릴 수 있습니다.
A5: - 모든 행의 data_status는 'AI 초안 (공식 확인 전)'입니다. 공식 출처에서 확인한 뒤 '확인 완료'로 바꾸세요. 확인 전 값은 perfumes.json으로 옮기지 않습니다 (CLAUDE.md 규칙 1번).
A7: ■ 색 구분
A8: - 회색 칸: AI 초안 (확인하고 틀리면 고치세요)
A9: - 노란 칸: 사람이 직접 채울 칸 (노트 출처 URL, 국내 정가, 확인일, 가격 출처, 이미지, 시향 가능 채널)
A11: ■ 해야 할 일 (향수마다)
A12: 1. notes_source_url에 공식 상품 페이지를 적고 top/middle/base 노트를 대조해 틀린 부분을 고친다
A13: 2. concentration(EDT/EDP 등)이 맞는지 확인한다. 모르면 비운다
A14: 3. kr_ml / kr_krw / kr_checked_at / kr_source_url에 국내 공식몰 정가를 적는다. 없으면 비워 둔다 (화면에 [확인 필요]로 표시됨)
A15: 4. 이미지를 public/perfumes/에 저장하고 image_file, image_source_url을 적는다
... A34: - 새 분위기 칩 '사랑스러운(lovely)', '매혹적인(sensual)'을 추가하고, 어울리는 향수 40개의 moods에 붙였습니다 (AI 판단이므로 맡아본 느낌에 맞게 고쳐도 됩니다).

Sheet perfumes
A1: id | B1: brand | C1: brand_ko | D1: name | E1: name_ko | F1: concentration | G1: top_notes | H1: middle_notes | I1: base_notes | J1: notes_source_url | K1: family | L1: sub_families | M1: moods | N1: avoid_flags | O1: intensity | P1: polarizing | Q1: season_occasion | R1: summary | S1: drydown | T1: check_point | U1: kr_ml | V1: kr_krw | W1: kr_checked_at | X1: kr_source_url | Y1: store_query | Z1: channels | AA1: image_file | AB1: image_source_url | AC1: data_status | AD1: todo
A2: acqua-di-parma-colonia | B2: Acqua di Parma | C2: 아쿠아 디 파르마 | D2: Colonia | E2: 콜로니아 | F2: EDC | G2: Bergamot, Lemon, Orange | H2: Lavender, Rosemary, Rose | I2: Sandalwood, Vetiver, Patchouli | K2: citrus | L2: aromatic | M2: clean, fresh, calm | O2: light | P2: low | Q2: 사계절 · 출근 | R2: 레몬과 라벤더가 어우러진 깔끔한 클래식 코롱 | S2: 몇 시간 뒤엔 부드러운 나무 향만 가볍게 남아요 | T2: 처음의 레몬 향이 라벤더와 나무 향으로 바뀌는지 맡아보세요 | Y2: 아쿠아 디 파르마 백화점 | Z2: [확인 필요] | AA2: acqua-di-parma-colonia.jpeg | AB2: https://kream.co.kr/products/226125 | AC2: AI 초안 (공식 확인 전) | AD2: 노트·농도 공식 확인 / 국내 정가 / 이미지 / 시향 가능 채널
A3: tom-ford-neroli-portofino | B3: Tom Ford | C3: 톰 포드 | D3: Neroli Portofino | E3: 네롤리 포르토피노 | F3: EDP | G3: Bergamot, Lemon, Mandarin | H3: Neroli, Orange Blossom, Lavender | I3: Amber | K3: citrus | L3: whiteFloral | M3: clean, zesty, elegant | O3: medium | P3: low | Q3: 봄·여름 · 휴가 | R3: 지중해 햇살 같은 시트러스와 오렌지 꽃 향 | S3: 몇 시간 뒤엔 부드러운 앰버가 살결에 은은히 남아요 | T3: 시트러스 뒤에 꽃 향이 얼마나 올라오는지 확인해 보세요 | Y3: 톰 포드 뷰티 백화점 | Z3: [확인 필요] | AC3: AI 초안 (공식 확인 전) | AD3: 노트·농도 공식 확인 / 국내 정가 / 이미지 / 시향 가능 채널
A4: dolce-gabbana-light-blue | B4: Dolce & Gabbana | C4: 돌체 앤 가바나 | D4: Light Blue | E4: 라이트 블루 | F4: EDT | G4: Lemon, Apple | H4: Bamboo, Jasmine, White Rose | I4: Cedar, Musk, Amber | K4: citrus | L4: fruity, aqua | M4: zesty, fresh, clean | O4: light | P4: low | Q4: 여름 · 데일리 | R4: 레몬과 사과의 청량한 여름 향 | S4: 시간이 지나면 가벼운 머스크와 시더가 남아요 | T4: 새콤한 첫 향이 얼마나 빨리 가라앉는지 맡아보세요 | Y4: 돌체앤가바나 백화점 | Z4: [확인 필요] | AC4: AI 초안 (공식 확인 전) | AD4: 노트·농도 공식 확인 / 국내 정가 / 이미지 / 시향 가능 채널
A5: calvin-klein-ck-one | B5: Calvin Klein | C5: 캘빈 클라인 | D5: CK One | E5: 씨케이 원 | F5: EDT | G5: Bergamot, Lemon, Pineapple | H5: Jasmine, Violet, Rose | I5: Musk, Amber, Cedar | K5: citrus | L5: musk, green | M5: clean, fresh, zesty | O5: light | P5: low | Q5: 사계절 · 데일리 | R5: 누구나 편하게 쓰는 깨끗한 시트러스 머스크 | S5: 몇 시간 뒤엔 깨끗한 비누 같은 머스크가 남아요 | T5: 상큼한 첫 향이 머스크로 넘어가는 과정을 맡아보세요 | Y5: 캘빈클라인 향수 백화점 | Z5: [확인 필요] | AC5: AI 초안 (공식 확인 전) | AD5: 노트·농도 공식 확인 / 국내 정가 / 이미지 / 시향 가능 채널
A6: jo-malone-english-pear-freesia | B6: Jo Malone London | C6: 조 말론 런던 | D6: English Pear & Freesia | E6: 잉글리시 페어 앤 프리지아 | F6: Cologne | G6: Pear | H6: Freesia, Rose | I6: Patchouli, Amber | K6: fruity | L6: floral | M6: soft, elegant, fresh, lovely | O6: light | P6: low | Q6: 가을 · 데일리 | R6: 잘 익은 배와 프리지아의 보드라운 향 | S6: 시간이 지나면 부드러운 패출리와 앰버가 따뜻하게 남아요 | T6: 배 향이 꽃 향으로 바뀌는 순간을 맡아보세요 | Y6: 조말론 런던 백화점 | Z6: [확인 필요] | AC6: AI 초안 (공식 확인 전) | AD6: 노트·농도 공식 확인 / 국내 정가 / 이미지 / 시향 가능 채널
A7: chanel-chance-eau-tendre | B7: Chanel | C7: 샤넬 | D7: Chance Eau Tendre | E7: 샹스 오 땅드르 | F7: EDT | G7: Grapefruit, Quince | H7: Jasmine | I7: White Musk, Iris, Cedar, Amber | K7: fruity | L7: whiteFloral, powdery | M7: soft, sweet, elegant, lovely | O7: light | P7: low | Q7: 봄 · 데이트 | R7: 새콤한 과일과 하얀 꽃이 만난 부드러운 향 | S7: 몇 시간 뒤엔 보송한 머스크가 포근하게 남아요 | T7: 과일 향 뒤에 보송한 느낌이 오는지 확인해 보세요 | Y7: 샤넬 뷰티 백화점 | Z7: [확인 필요] | AC7: AI 초안 (공식 확인 전) | AD7: 노트·농도 공식 확인 / 국내 정가 / 이미지 / 시향 가능 채널
A8: burberry-her | B8: Burberry | C8: 버버리 | D8: Her | E8: 허 | F8: EDP | G8: Blackberry, Raspberry, Strawberry | H8: Jasmine, Violet | I8: Amber, Musk, Vanilla | K8: fruity | L8: gourmand | M8: sweet, cozy, warm, lovely | N8: tooSweet | O8: medium | P8: mid | Q8: 가을·겨울 · 데이트 | R8: 베리 잼처럼 달콤하고 진한 과일 향 | S8: 몇 시간 뒤엔 달콤한 바닐라 머스크가 남아요 | T8: 첫 향의 달콤함이 부담스럽지 않은지 맡아보세요 | U8: 50 | V8: 189000 | W8: 2026-10-07 | X8: https://kr.burberry.com/her-eau-de-parfum-50ml-p40804581 | Y8: 버버리 향수 백화점 | Z8: [확인 필요] | AA8: burberry-her.jpg | AB8: https://kr.burberry.com/her-eau-de-parfum-50ml-p40804581 | AC8: AI 초안 (공식 확인 전) | AD8: 노트·농도 공식 확인 / 시향 가능 채널 (가격·이미지는 공식 페이지에서 반영됨)
A9: marc-jacobs-daisy | B9: Marc Jacobs | C9: 마크 제이콥스 | D9: Daisy | E9: 데이지 | F9: EDT | G9: Strawberry, Violet Leaf, Grapefruit | H9: Violet, Jasmine | I9: Musk, Vanilla, Cedar | K9: fruity | L9: floral | M9: soft, sweet, zesty, lovely | O9: light | P9: low | Q9: 봄 · 데일리 | R9: 딸기와 꽃이 어우러진 발랄한 향 | S9: 시간이 지나면 보송한 머스크와 가벼운 바닐라가 남아요 | T9: 딸기 향이 꽃 향으로 이어지는 변화를 맡아보세요 | Y9: 마크제이콥스 데이지 백화점 | Z9: [확인 필요] | AC9: AI 초안 (공식 확인 전) | AD9: 노트·농도 공식 확인 / 국내 정가 / 이미지 / 시향 가능 채널
A10: armani-si-edp | B10: Giorgio Armani | C10: 조르지오 아르마니 | D10: Si | E10: 시 | F10: EDP | G10: Blackcurrant, Mandarin | H10: Freesia, Rose | I10: Vanilla, Patchouli, Amber, Musk | K10: fruity | L10: amber, floral | M10: elegant, warm, sweet | O10: medium | P10: mid | Q10: 가을·겨울 · 저녁 | R10: 새콤한 베리와 바닐라가 어우러진 세련된 향 | S10: 몇 시간 뒤엔 부드러운 바닐라와 앰버가 남아요 | T10: 베리 향이 바닐라로 넘어갈 때 달콤함의 정도를 확인해 보세요 | Y10: 조르지오 아르마니 뷰티 백화점 | Z10: [확인 필요] | AC10: AI 초안 (공식 확인 전) | AD10: 노트·농도 공식 확인 / 국내 정가 / 이미지 / 시향 가능 채널
A11: davidoff-cool-water-man | B11: Davidoff | C11: 다비도프 | D11: Cool Water Man | E11: 쿨 워터 맨 | F11: EDT | G11: Mint, Lavender, Sea Notes | H11: Geranium, Neroli, Jasmine | I11: Oakmoss, Amber, Musk, Cedar | K11: aqua | L11: aromatic | M11: cool, clean, fresh | O11: light | P11: low | Q11: 여름 · 운동 후 | R11: 바닷바람 같은 시원하고 깨끗한 향 | S11: 시간이 지나면 가벼운 이끼와 머스크가 남아요 | T11: 민트의 시원함이 얼마나 오래가는지 맡아보세요 | Y11: 다비도프 쿨워터 백화점 | Z11: [확인 필요] | AC11: AI 초안 (공식 확인 전) | AD11: 노트·농도 공식 확인 / 국내 정가 / 이미지 / 시향 가능 채널
A12: jo-malone-wood-sage-sea-salt | B12: Jo Malone London | C12: 조 말론 런던 | D12: Wood Sage & Sea Salt | E12: 우드 세이지 앤 씨 솔트 | F12: Cologne | G12: Grapefruit, Sea Salt | H12: Sage | I12: Ambrette | K12: aqua | L12: green, aromatic | M12: cool, calm, fresh | O12: light | P12: low | Q12: 봄·여름 · 산책 | R12: 바닷가 절벽을 걷는 듯한 짭짤하고 깨끗한 향 | S12: 시간이 지나면 보송한 머스크 느낌만 가볍게 남아요 | T12: 소금과 허브 향이 얼마나 조화로운지 맡아보세요 | Y12: 조말론 런던 백화점 | Z12: [확인 필요] | AC12: AI 초안 (공식 확인 전) | AD12: 노트·농도 공식 확인 / 국내 정가 / 이미지 / 시향 가능 채널
A13: armani-acqua-di-gio-homme | B13: Giorgio Armani | C13: 조르지오 아르마니 | D13: Acqua di Giò Pour Homme | E13: 아쿠아 디 지오 뿌르 옴므 | F13: EDT | G13: Lime, Lemon, Bergamot | H13: Sea Notes, Jasmine, Rosemary | I13: White Musk, Cedar, Patchouli, Oakmoss | K13: aqua | L13: citrus | M13: cool, clean, fresh | O13: medium | P13: low | Q13: 여름 · 출근 | R13: 시원한 바다와 시트러스의 정석 같은 향 | S13: 몇 시간 뒤엔 깨끗한 머스크와 나무 향이 남아요 | T13: 시트러스 뒤에 바다 느낌이 오는지 확인해 보세요 | Y13: 조르지오 아르마니 뷰티 백화점 | Z13: [확인 필요] | AC13: AI 초안 (공식 확인 전) | AD13: 노트·농도 공식 확인 / 국내 정가 / 이미지 / 시향 가능 채널
A14: diptyque-philosykos | B14: Diptyque | C14: 딥티크 | D14: Philosykos | E14: 필로시코스 | F14: EDT | G14: Fig Leaf | H14: Fig, Coconut | I14: Cedar | K14: green | L14: woody, fruity | M14: fresh, calm, soft | O14: medium | P14: mid | Q14: 봄·여름 · 휴식 | R14: 무화과나무 그늘 아래 같은 푸릇하고 부드러운 향 | S14: 시간이 지나면 우유 같은 나무 향이 조용히 남아요 | T14: 풀 향과 달콤한 열매 향의 균형을 맡아보세요 | Y14: 딥티크 백화점 | Z14: [확인 필요] | AC14: AI 초안 (공식 확인 전) | AD14: 노트·농도 공식 확인 / 국내 정가 / 이미지 / 시향 가능 채널
A15: hermes-un-jardin-sur-le-nil | B15: Hermès | C15: 에르메스 | D15: Un Jardin sur le Nil | E15: 나일 강의 정원 | F15: EDT | G15: Green Mango, Grapefruit, Tomato Leaf | H15: Lotus | I15: Incense, Cedar | K15: green | L15: fruity, aqua | M15: fresh, cool, soft | O15: light | P15: low | Q15: 봄·여름 · 데일리 | R15: 덜 익은 망고와 연꽃의 청량한 정원 향 | S15: 시간이 지나면 은은한 인센스와 나무 향이 가볍게 남아요 | T15: 망고의 풋풋함이 부담스럽지 않은지 맡아보세요 | Y15: 에르메스 뷰티 백화점 | Z15: [확인 필요] | AC15: AI 초안 (공식 확인 전) | AD15: 노트·농도 공식 확인 / 국내 정가 / 이미지 / 시향 가능 채널
A16: bvlgari-eau-parfumee-the-vert | B16: Bvlgari | C16: 불가리 | D16: Eau Parfumée au Thé Vert | E16: 오 파푸메 오 떼 베르 | F16: EDC | G16: Bergamot, Orange, Coriander | H16: Green Tea, Jasmine | I16: Musk, Oakmoss, Cedar | K16: green | L16: citrus, musk | M16: fresh, clean, calm | O16: light | P16: low | Q16: 사계절 · 출근 | R16: 녹차를 우린 듯한 맑고 깨끗한 향 | S16: 몇 시간 뒤엔 가벼운 머스크가 은은하게 남아요 | T16: 차 향이 시트러스 뒤에 얼마나 깔끔하게 나는지 맡아보세요 | Y16: 불가리 향수 백화점 | Z16: [확인 필요] | AC16: AI 초안 (공식 확인 전) | AD16: 노트·농도 공식 확인 / 국내 정가 / 이미지 / 시향 가능 채널
A17: dior-sauvage-edt | B17: Dior | C17: 디올 | D17: Sauvage | E17: 소바쥬 | F17: EDT | G17: Bergamot, Pepper | H17: Lavender, Geranium, Vetiver | I17: Ambroxan, Cedar, Labdanum | K17: aromatic | L17: spicy, woody | M17: cool, deep, fresh | O17: medium | P17: mid | Q17: 사계절 · 데이트 | R17: 상쾌한 시트러스와 후추, 깨끗한 나무 향 | S17: 몇 시간 뒤엔 깔끔한 앰버와 나무 향이 남아요 | T17: 첫 향의 후추 느낌이 얼마나 강한지 맡아보세요 | Y17: 디올 뷰티 백화점 | Z17: [확인 필요] | AC17: AI 초안 (공식 확인 전) | AD17: 노트·농도 공식 확인 / 국내 정가 / 이미지 / 시향 가능 채널
A18: chanel-bleu-de-chanel-edp | B18: Chanel | C18: 샤넬 | D18: Bleu de Chanel | E18: 블루 드 샤넬 | F18: EDP | G18: Grapefruit, Lemon, Mint, Pink Pepper | H18: Ginger, Nutmeg, Jasmine | I18: Incense, Cedar, Sandalwood, Patchouli | K18: aromatic | L18: woody, citrus | M18: calm, deep, clean | O18: medium | P18: low | Q18: 사계절 · 출근 | R18: 상큼한 시트러스에서 깊은 나무 향으로 이어지는 단정한 향 | S18: 몇 시간 뒤엔 차분한 우디 향이 남아요 | T18: 첫 향의 자몽이 나무 향으로 바뀌는 흐름을 맡아보세요 | Y18: 샤넬 뷰티 백화점 | Z18: [확인 필요] | AC18: AI 초안 (공식 확인 전) | AD18: 노트·농도 공식 확인 / 국내 정가 / 이미지 / 시향 가능 채널
A19: jean-paul-gaultier-le-male | B19: Jean Paul Gaultier | C19: 장 폴 고티에 | D19: Le Male | E19: 르 말 | F19: EDT | G19: Mint, Lavender, Bergamot, Cardamom | H19: Cinnamon, Orange Blossom | I19: Vanilla, Tonka Bean, Sandalwood, Amber | K19: aromatic | L19: gourmand, spicy | M19: cozy, warm, sweet | N19: tooSweet | O19: strong | P19: mid | Q19: 가을·겨울 · 저녁 | R19: 라벤더와 바닐라가 만난 달콤하고 따뜻한 향 | S19: 몇 시간 뒤엔 포근한 바닐라 향이 오래 남아요 | T19: 달콤한 바닐라 느낌이 부담스럽지 않은지 확인해 보세요 | Y19: 장폴고티에 향수 백화점 | Z19: [확인 필요] | AC19: AI 초안 (공식 확인 전) | AD19: 노트·농도 공식 확인 / 국내 정가 / 이미지 / 시향 가능 채널
A20: viktor-rolf-flowerbomb | B20: Viktor&Rolf | C20: 빅터 앤 롤프 | D20: Flowerbomb | E20: 플라워밤 | F20: EDP | G20: Bergamot, Tea | H20: Jasmine, Orchid, Rose, Freesia | I20: Patchouli, Musk | K20: floral | L20: whiteFloral | M20: elegant, sweet, warm, lovely | N20: heavyFloral | O20: strong | P20: high | Q20: 가을·겨울 · 저녁 | R20: 꽃다발이 터지는 듯한 화려한 꽃 향 | S20: 시간이 지나면 달콤한 패출리와 머스크가 남아요 | T20: 꽃 향이 진해서 호불호가 갈릴 수 있으니 한 번에 길게 맡아보세요 | Y20: 빅터앤롤프 플라워밤 백화점 | Z20: [확인 필요] | AC20: AI 초안 (공식 확인 전) | AD20: 노트·농도 공식 확인 / 국내 정가 / 이미지 / 시향 가능 채널
A21: dior-miss-dior-blooming-bouquet | B21: Dior | C21: 디올 | D21: Miss Dior Blooming Bouquet | E21: 미스 디올 블루밍 부케 | F21: EDT | G21: Mandarin, Bergamot | H21: Peony, Damask Rose | I21: White Musk | K21: floral | L21: musk, citrus | M21: elegant, soft, fresh, lovely | O21: light | P21: low | Q21: 봄 · 데이트 | R21: 작약과 장미가 싱그럽게 피어나는 가벼운 꽃 향 | S21: 몇 시간 뒤엔 보송한 화이트 머스크가 남아요 | T21: 꽃 향이 가볍게 퍼지는지 손목에 뿌려 맡아보세요 | Y21: 디올 뷰티 백화점 | Z21: [확인 필요] | AC21: AI 초안 (공식 확인 전) | AD21: 노트·농도 공식 확인 / 국내 정가 / 이미지 / 시향 가능 채널
A22: jo-malone-peony-blush-suede | B22: Jo Malone London | C22: 조 말론 런던 | D22: Peony & Blush Suede | E22: 피오니 앤 블러쉬 스웨이드 | F22: Cologne | G22: Apple | H22: Peony, Jasmine, Rose | I22: Suede | K22: floral | L22: powdery, leather | M22: elegant, soft, warm, lovely | O22: medium | P22: mid | Q22: 봄·가을 · 데이트 | R22: 작약과 장미를 부드러운 스웨이드가 감싸는 향 | S22: 시간이 지나면 보들보들한 가죽 느낌이 남아요 | T22: 꽃 향 뒤에 스웨이드가 느껴지는지 맡아보세요 | Y22: 조말론 런던 백화점 | Z22: [확인 필요] | AC22: AI 초안 (공식 확인 전) | AD22: 노트·농도 공식 확인 / 국내 정가 / 이미지 / 시향 가능 채널
A23: chanel-coco-mademoiselle | B23: Chanel | C23: 샤넬 | D23: Coco Mademoiselle | E23: 코코 마드모아젤 | F23: EDP | G23: Orange, Bergamot, Grapefruit | H23: Jasmine, Rose | I23: Patchouli, Vetiver, Vanilla, White Musk | K23: floral | L23: citrus, woody | M23: elegant, warm, fresh | O23: medium | P23: low | Q23: 사계절 · 데이트 | R23: 상큼한 시트러스와 장미가 조화로운 세련된 향 | S23: 몇 시간 뒤엔 패출리와 바닐라가 부드럽게 남아요 | T23: 시트러스에서 꽃, 나무 향으로 바뀌는 흐름을 맡아보세요 | Y23: 샤넬 뷰티 백화점 | Z23: [확인 필요] | AC23: AI 초안 (공식 확인 전) | AD23: 노트·농도 공식 확인 / 국내 정가 / 이미지 / 시향 가능 채널
A24: dior-jadore-edp | B24: Dior | C24: 디올 | D24: J'adore | E24: 쟈도르 | F24: EDP | G24: Pear, Bergamot, Magnolia | H24: Jasmine, Rose | I24: Musk, Vanilla, Cedar | K24: whiteFloral | L24: floral, fruity | M24: elegant, sweet, soft, lovely | O24: medium | P24: mid | Q24: 사계절 · 데이트 | R24: 과즙 같은 첫 향과 우아한 하얀 꽃 향 | S24: 몇 시간 뒤엔 부드러운 머스크와 바닐라가 남아요 | T24: 꽃 향이 진한 정도를 손목에서 확인해 보세요 | Y24: 디올 뷰티 백화점 | Z24: [확인 필요] | AC24: AI 초안 (공식 확인 전) | AD24: 노트·농도 공식 확인 / 국내 정가 / 이미지 / 시향 가능 채널
A25: gucci-bloom | B25: Gucci | C25: 구찌 | D25: Bloom | E25: 블룸 | F25: EDP | G25: Jasmine | H25: Tuberose | I25: Rangoon Creeper | K25: whiteFloral | L25: floral | M25: elegant, soft, lovely | N25: heavyFloral | O25: medium | P25: mid | Q25: 봄·가을 · 데이트 | R25: 하얀 꽃이 가득한 정원 같은 진한 꽃 향 | S25: 시간이 지나도 꽃 향이 은은하게 이어져요 | T25: 꽃 향이 진한 편이라 호불호가 있는지 확인해 보세요 | Y25: 구찌 뷰티 백화점 | Z25: [확인 필요] | AC25: AI 초안 (공식 확인 전) | AD25: 노트·농도 공식 확인 / 국내 정가 / 이미지 / 시향 가능 채널
A26: diptyque-do-son | B26: Diptyque | C26: 딥티크 | D26: Do Son | E26: 도 손 | F26: EDT | G26: Orange Blossom, Pink Pepper | H26: Tuberose, Jasmine | I26: Iris, Musk | K26: whiteFloral | L26: powdery, musk | M26: elegant, soft, calm | O26: medium | P26: mid | Q26: 여름 · 저녁 | R26: 달콤한 하얀 꽃과 보송한 머스크가 어우러진 향 | S26: 시간이 지나면 보송한 분내가 잔잔하게 남아요 | T26: 튜베로즈의 진함이 부담스럽지 않은지 맡아보세요 | Y26: 딥티크 백화점 | Z26: [확인 필요] | AC26: AI 초안 (공식 확인 전) | AD26: 노트·농도 공식 확인 / 국내 정가 / 이미지 / 시향 가능 채널
A27: chanel-no5-edp | B27: Chanel | C27: 샤넬 | D27: N°5 | E27: N°5 | F27: EDP | G27: Aldehydes, Neroli, Bergamot | H27: Jasmine, Rose, Ylang-Ylang, Iris | I27: Sandalwood, Vetiver, Vanilla, Amber | K27: whiteFloral | L27: powdery, musk | M27: elegant, calm | N27: powdery, heavyFloral | O27: medium | P27: high | Q27: 가을·겨울 · 격식 | R27: 비누처럼 반짝이는 꽃 향의 클래식 | S27: 시간이 지나면 보송한 파우더 느낌이 남아요 | T27: 첫 향의 알데하이드가 낯설지 않은지 확인해 보세요 | Y27: 샤넬 뷰티 백화점 | Z27: [확인 필요] | AC27: AI 초안 (공식 확인 전) | AD27: 노트·농도 공식 확인 / 국내 정가 / 이미지 / 시향 가능 채널
A28: prada-infusion-d-iris | B28: Prada | C28: 프라다 | D28: Infusion d'Iris | E28: 인퓨전 디리스 | F28: EDP | G28: Mandarin, Galbanum, Neroli | H28: Iris | I28: Benzoin, Vetiver, Cedar, Incense | K28: powdery | L28: green, woody | M28: calm, soft, elegant | N28: powdery | O28: medium | P28: mid | Q28: 사계절 · 출근 | R28: 아이리스의 보송하고 깨끗한 분 향 | S28: 시간이 지나면 부드러운 나무와 인센스가 남아요 | T28: 보송한 분 느낌이 얼마나 강한지 맡아보세요 | Y28: 프라다 뷰티 백화점 | Z28: [확인 필요] | AC28: AI 초안 (공식 확인 전) | AD28: 노트·농도 공식 확인 / 국내 정가 / 이미지 / 시향 가능 채널
A29: dior-homme-intense | B29: Dior | C29: 디올 | D29: Dior Homme Intense | E29: 디올 옴므 앵땅스 | F29: EDP | G29: Lavender, Pear | H29: Iris, Ambrette, Cacao | I29: Cedar, Vetiver | K29: powdery | L29: woody, gourmand | M29: calm, deep, soft | N29: powdery | O29: medium | P29: mid | Q29: 가을·겨울 · 저녁 | R29: 아이리스와 카카오가 어우러진 부드럽고 깊은 향 | S29: 몇 시간 뒤엔 차분한 나무 향이 남아요 | T29: 아이리스의 분 느낌과 카카오의 달콤함을 맡아보세요 | Y29: 디올 뷰티 백화점 | Z29: [확인 필요] | AC29: AI 초안 (공식 확인 전) | AD29: 노트·농도 공식 확인 / 국내 정가 / 이미지 / 시향 가능 채널
A30: chloe-edp | B30: Chloé | C30: 끌로에 | D30: Chloé Eau de Parfum | E30: 끌로에 오 드 퍼퓸 | F30: EDP | G30: Peony, Lychee, Freesia | H30: Rose, Lily of the Valley, Magnolia | I30: Cedar, Amber | K30: powdery | L30: floral | M30: soft, elegant, calm, lovely | N30: powdery | O30: medium | P30: low | Q30: 봄·가을 · 데일리 | R30: 보송한 장미와 작약의 부드러운 꽃 향 | S30: 몇 시간 뒤엔 은은한 장미와 나무 향이 남아요 | T30: 장미 향이 분 향처럼 느껴지는지 맡아보세요 | Y30: 끌로에 향수 백화점 | Z30: [확인 필요] | AC30: AI 초안 (공식 확인 전) | AD30: 노트·농도 공식 확인 / 국내 정가 / 이미지 / 시향 가능 채널
A31: byredo-blanche | B31: Byredo | C31: 바이레도 | D31: Blanche | E31: 블랑쉬 | F31: EDP | G31: Aldehydes, Pink Pepper | H31: White Rose, Peony, Violet | I31: Musk, Sandalwood | K31: musk | L31: floral | M31: clean, soft, calm | O31: light | P31: low | Q31: 사계절 · 데일리 | R31: 갓 빨아 말린 하얀 시트 같은 깨끗한 향 | S31: 몇 시간 뒤엔 보송한 머스크가 피부에 남아요 | T31: 깨끗한 비누 느낌이 오래가는지 확인해 보세요 | U31: 50 | V31: 305000 | W31: 2026-10-07 | X31: https://www.byredo.com/ko_kr/p/blanche-eau-de-parfum | Y31: 바이레도 백화점 | Z31: [확인 필요] | AA31: byredo-blanche.jpg | AB31: https://www.byredo.com/ko_kr/p/blanche-eau-de-parfum | AC31: AI 초안 (공식 확인 전) | AD31: 노트·농도 공식 확인 / 시향 가능 채널 (가격·이미지는 공식 페이지에서 반영됨)
A32: maison-margiela-replica-lazy-sunday-morning | B32: Maison Margiela | C32: 메종 마르지엘라 | D32: Replica Lazy Sunday Morning | E32: 레플리카 레이지 선데이 모닝 | F32: EDT | G32: Pear, Lily of the Valley | H32: Rose, Iris | I32: White Musk, Patchouli | K32: musk | L32: powdery, fruity | M32: clean, soft, cozy | O32: light | P32: low | Q32: 사계절 · 휴일 | R32: 햇살 드는 침대 시트 같은 포근하고 깨끗한 향 | S32: 시간이 지나면 보송한 머스크가 오래 남아요 | T32: 첫 향의 배와 은방울꽃이 머스크로 이어지는지 맡아보세요 | U32: 100 | V32: 240000 | W32: 2026-10-07 | X32: https://www.maisonmargiela.com/ko-kr/%EB%A0%88%ED%94%8C%EB%A6%AC%EC%B9%B4-%EB%A0%88%EC%9D%B4%EC%A7%80-%EC%84%A0%EB%8D%B0%EC%9D%B4-%EB%AA%A8%EB%8B%9D-%EC%98%A4-%EB%93%9C-%EB%9A%9C%EC%99%88%EB%A0%9B-S33YX0018S10932001.html | Y32: 메종 마르지엘라 레플리카 백화점 | Z32: [확인 필요] | AA32: maison-margiela-replica-lazy-sunday-morning.jpg | AB32: https://www.maisonmargiela.com/ko-kr/%EB%A0%88%ED%94%8C%EB%A6%AC%EC%B9%B4-%EB%A0%88%EC%9D%B4%EC%A7%80-%EC%84%A0%EB%8D%B0%EC%9D%B4-%EB%AA%A8%EB%8B%9D-%EC%98%A4-%EB%93%9C-%EB%9A%9C%EC%99%88%EB%A0%9B-S33YX0018S10932001.html | AC32: AI 초안 (공식 확인 전) | AD32: 노트·농도 공식 확인 / 시향 가능 채널 (가격·이미지는 공식 페이지에서 반영됨)
A33: narciso-rodriguez-for-her-edp | B33: Narciso Rodriguez | C33: 나르시소 로드리게즈 | D33: For Her Eau de Parfum | E33: 포 허 오 드 퍼퓸 | F33: EDP | G33: Orange Blossom, Osmanthus | H33: Rose | I33: Musk, Amber, Patchouli | K33: musk | L33: floral, amber | M33: soft, elegant, warm | O33: medium | P33: mid | Q33: 사계절 · 데이트 | R33: 꽃 향이 살결 같은 머스크에 스며든 향 | S33: 몇 시간 뒤엔 따뜻한 머스크가 오래 남아요 | T33: 머스크가 포근한지 답답한지 손목에서 확인해 보세요 | Y33: 나르시소 로드리게즈 백화점 | Z33: [확인 필요] | AC33: AI 초안 (공식 확인 전) | AD33: 노트·농도 공식 확인 / 국내 정가 / 이미지 / 시향 가능 채널
A34: diptyque-fleur-de-peau | B34: Diptyque | C34: 딥티크 | D34: Fleur de Peau | E34: 플뢰르 드 뽀 | F34: EDP | G34: Bergamot, Pink Pepper | H34: Iris, Rose | I34: Ambrette, Musk | K34: musk | L34: powdery | M34: soft, clean, calm | O34: medium | P34: mid | Q34: 사계절 · 저녁 | R34: 맨살의 온기 같은 보송한 머스크 | S34: 시간이 지나면 부드러운 피부 향처럼 남아요 | T34: 머스크가 깨끗하게 느껴지는지 맡아보세요 | Y34: 딥티크 백화점 | Z34: [확인 필요] | AC34: AI 초안 (공식 확인 전) | AD34: 노트·농도 공식 확인 / 국내 정가 / 이미지 / 시향 가능 채널
A35: maison-margiela-replica-beach-walk | B35: Maison Margiela | C35: 메종 마르지엘라 | D35: Replica Beach Walk | E35: 레플리카 비치 워크 | F35: EDT | G35: Bergamot, Lemon, Pink Pepper | H35: Coconut Milk, Heliotrope, Ylang-Ylang | I35: Musk, Cedar, Benzoin | K35: musk | L35: gourmand, citrus | M35: fresh, warm, sweet | O35: light | P35: low | Q35: 여름 · 휴가 | R35: 선크림과 코코넛이 어우러진 휴양지 같은 향 | S35: 시간이 지나면 부드럽고 달콤한 머스크가 남아요 | T35: 첫 향의 시트러스가 코코넛으로 바뀌는 순간을 맡아보세요 | Y35: 메종 마르지엘라 레플리카 백화점 | Z35: [확인 필요] | AC35: AI 초안 (공식 확인 전) | AD35: 노트·농도 공식 확인 / 국내 정가 / 이미지 / 시향 가능 채널
A36: hermes-terre-d-hermes-edt | B36: Hermès | C36: 에르메스 | D36: Terre d'Hermès | E36: 테르 데르메스 | F36: EDT | G36: Orange, Grapefruit | H36: Pepper, Geranium, Flint | I36: Vetiver, Patchouli, Benzoin, Cedar | K36: spicy | L36: woody, citrus | M36: deep, calm, warm | O36: medium | P36: mid | Q36: 사계절 · 출근 | R36: 오렌지와 후추, 흙냄새 나는 나무 향이 어우러진 향 | S36: 몇 시간 뒤엔 차분한 베티버와 나무 향이 남아요 | T36: 첫 향의 후추와 광물 느낌이 낯설지 않은지 확인해 보세요 | Y36: 에르메스 뷰티 백화점 | Z36: [확인 필요] | AC36: AI 초안 (공식 확인 전) | AD36: 노트·농도 공식 확인 / 국내 정가 / 이미지 / 시향 가능 채널
A37: hermes-twilly-d-hermes | B37: Hermès | C37: 에르메스 | D37: Twilly d'Hermès | E37: 트윌리 데르메스 | F37: EDP | G37: Ginger | H37: Tuberose | I37: Sandalwood | K37: spicy | L37: whiteFloral, woody | M37: warm, elegant, fresh | O37: medium | P37: mid | Q37: 사계절 · 데일리 | R37: 톡 쏘는 생강과 하얀 꽃이 만난 발랄한 향 | S37: 시간이 지나면 부드러운 샌달우드가 남아요 | T37: 생강의 알싸함과 꽃 향의 조화를 맡아보세요 | Y37: 에르메스 뷰티 백화점 | Z37: [확인 필요] | AC37: AI 초안 (공식 확인 전) | AD37: 노트·농도 공식 확인 / 국내 정가 / 이미지 / 시향 가능 채널
A38: le-labo-santal-33 | B38: Le Labo | C38: 르 라보 | D38: Santal 33 | E38: 상탈 33 | F38: EDP | G38: Cardamom, Violet | H38: Iris, Papyrus | I38: Sandalwood, Cedar, Leather, Ambroxan | K38: woody | L38: leather, spicy | M38: deep, calm, warm, sensual | N38: tooStrong | O38: strong | P38: high | Q38: 가을·겨울 · 저녁 | R38: 가죽과 샌달우드가 어우러진 진하고 건조한 나무 향 | S38: 시간이 지나도 나무와 가죽 향이 오래 남아요 | T38: 향이 진하니 한 번만 뿌려 시간이 지나며 변화를 확인해 보세요 | U38: 50 | V38: 319000 | W38: 2026-10-07 | X38: https://www.lelabofragrances.co.kr/santal-33-987.html | Y38: 르 라보 백화점 | Z38: [확인 필요] | AA38: le-labo-santal-33.jpg | AB38: https://www.lelabofragrances.co.kr/santal-33-987.html | AC38: AI 초안 (공식 확인 전) | AD38: 노트·농도 공식 확인 / 시향 가능 채널 (가격·이미지는 공식 페이지에서 반영됨)
A39: diptyque-tam-dao | B39: Diptyque | C39: 딥티크 | D39: Tam Dao | E39: 탐 다오 | F39: EDP | G39: Cypress, Rosewood | H39: Sandalwood | I39: Cedar, Amber | K39: woody | L39: amber | M39: calm, cozy, deep | O39: medium | P39: low | Q39: 가을·겨울 · 휴식 | R39: 숲속 오두막 같은 포근한 샌달우드 향 | S39: 시간이 지나면 부드러운 나무 향이 따뜻하게 남아요 | T39: 첫 향의 사이프러스가 샌달우드로 바뀌는 흐름을 맡아보세요 | Y39: 딥티크 백화점 | Z39: [확인 필요] | AC39: AI 초안 (공식 확인 전) | AD39: 노트·농도 공식 확인 / 국내 정가 / 이미지 / 시향 가능 채널
A40: tom-ford-oud-wood | B40: Tom Ford | C40: 톰 포드 | D40: Oud Wood | E40: 우드 우드 | F40: EDP | G40: Rosewood, Cardamom, Pepper | H40: Oud, Sandalwood | I40: Vetiver, Tonka Bean, Amber | K40: woody | L40: spicy, amber | M40: deep, warm, elegant, sensual | N40: tooStrong | O40: strong | P40: high | Q40: 가을·겨울 · 저녁 | R40: 고급스럽고 진한 침향과 샌달우드 향 | S40: 시간이 지나도 우디한 향이 오래 남아요 | T40: 우드 향의 진함이 부담스러운지 확인해 보세요 | Y40: 톰 포드 뷰티 백화점 | Z40: [확인 필요] | AC40: AI 초안 (공식 확인 전) | AD40: 노트·농도 공식 확인 / 국내 정가 / 이미지 / 시향 가능 채널
...

Sheet notes
A1: ingredient_en | B1: ingredient_ko | C1: feel | D1: family | E1: used_in
A2: Aldehydes | B2: 알데하이드 | C2: 비누처럼 깨끗하고 반짝이는 향 | D2: musk | E2: =COUNTIF(perfumes!$G$2:$I$100,"*"&A2&"*")
A3: Amber | B3: 앰버 | C3: 따뜻하고 달콤한 수지 향 | D3: amber | E3: =COUNTIF(perfumes!$G$2:$I$100,"*"&A3&"*")
A4: Ambergris | B4: 앰버그리스 | C4: 따뜻하고 짭짤한 바다 같은 부드러운 향 | D4: amber | E4: =COUNTIF(perfumes!$G$2:$I$100,"*"&A4&"*")
A5: Amberwood | B5: 앰버우드 | C5: 따뜻하고 달콤한 나무 향 | D5: amber | E5: =COUNTIF(perfumes!$G$2:$I$100,"*"&A5&"*")
A6: Ambrette | B6: 앰브레트 | C6: 따뜻한 피부와 꽃을 닮은 은은한 향 | D6: musk | E6: =COUNTIF(perfumes!$G$2:$I$100,"*"&A6&"*")
A7: Ambroxan | B7: 암브록산 | C7: 깨끗하고 따뜻한 피부 같은 은은한 향 | D7: musk | E7: =COUNTIF(perfumes!$G$2:$I$100,"*"&A7&"*")
A8: Apple | B8: 사과 | C8: 아삭하고 풋풋한 사과 향 | D8: fruity | E8: =COUNTIF(perfumes!$G$2:$I$100,"*"&A8&"*")
A9: Bamboo | B9: 대나무 | C9: 맑고 푸릇한 대나무 잎 향 | D9: green | E9: =COUNTIF(perfumes!$G$2:$I$100,"*"&A9&"*")
A10: Benzoin | B10: 벤조인 | C10: 달콤하고 따뜻한 수지 향 | D10: amber | E10: =COUNTIF(perfumes!$G$2:$I$100,"*"&A10&"*")
A11: Bergamot | B11: 베르가못 | C11: 상큼하고 살짝 쌉쌀한 귤 껍질 향 | D11: citrus | E11: =COUNTIF(perfumes!$G$2:$I$100,"*"&A11&"*")
A12: Blackberry | B12: 블랙베리 | C12: 진하고 달콤새콤한 베리 향 | D12: fruity | E12: =COUNTIF(perfumes!$G$2:$I$100,"*"&A12&"*")
A13: Blackcurrant | B13: 블랙커런트 | C13: 새콤하고 진한 검은 베리 향 | D13: fruity | E13: =COUNTIF(perfumes!$G$2:$I$100,"*"&A13&"*")
... A124: Yuzu | B124: 유자 | C124: 향긋하고 쌉쌀한 유자 껍질 향 | D124: citrus | E124: =COUNTIF(perfumes!$G$2:$I$100,"*"&A124&"*")

Sheet options
A1: 향 계열 (family) | G1: 분위기 칩 (moods) | I1: 시트1 사용 수 | K1: 피하고 싶은 칩 (avoid_flags)
A2: id | B2: 이름 | C2: 시향 순서 | D2: 예시 | E2: 시트1 등록 수 | G2: calm | H2: 차분한 | I2: =COUNTIF(perfumes!$M$2:$M$200,"*"&G2&"*") | K2: tooSweet | L2: 너무 단 향
A3: citrus | B3: 시트러스 | C3: 1 | D3: 레몬·베르가못·자몽 | E3: =COUNTIF(perfumes!$K$2:$K$200,A3) | G3: clean | H3: 깨끗한 | I3: =COUNTIF(perfumes!$M$2:$M$200,"*"&G3&"*") | K3: tooStrong | L3: 너무 진한 향
A4: fruity | B4: 프루티 | C4: 2 | D4: 복숭아·배·베리 | E4: =COUNTIF(perfumes!$K$2:$K$200,A4) | G4: cool | H4: 시원한 | I4: =COUNTIF(perfumes!$M$2:$M$200,"*"&G4&"*") | K4: headache | L4: 머리 아픈 향
A5: aqua | B5: 아쿠아·오존 | C5: 3 | D5: 바다·빗물·바람 | E5: =COUNTIF(perfumes!$K$2:$K$200,A5) | G5: cozy | H5: 포근한 | I5: =COUNTIF(perfumes!$M$2:$M$200,"*"&G5&"*") | K5: heavyFloral | L5: 꽃향이 강한 향
A6: green | B6: 그린 | C6: 4 | D6: 풀잎·녹차·무화과잎 | E6: =COUNTIF(perfumes!$K$2:$K$200,A6) | G6: fresh | H6: 싱그러운 | I6: =COUNTIF(perfumes!$M$2:$M$200,"*"&G6&"*") | K6: smoky | L6: 스모키한 향
A7: aromatic | B7: 아로마틱 | C7: 5 | D7: 라벤더·로즈마리·민트 | E7: =COUNTIF(perfumes!$K$2:$K$200,A7) | G7: zesty | H7: 상큼한 | I7: =COUNTIF(perfumes!$M$2:$M$200,"*"&G7&"*") | K7: powdery | L7: 화장품 파우더 향
A8: floral | B8: 플로럴 | C8: 6 | D8: 장미·작약·은방울꽃 | E8: =COUNTIF(perfumes!$K$2:$K$200,A8) | G8: warm | H8: 따뜻한 | I8: =COUNTIF(perfumes!$M$2:$M$200,"*"&G8&"*")
A9: whiteFloral | B9: 화이트 플로럴 | C9: 7 | D9: 자스민·튜베로즈·오렌지꽃 | E9: =COUNTIF(perfumes!$K$2:$K$200,A9) | G9: sweet | H9: 달콤한 | I9: =COUNTIF(perfumes!$M$2:$M$200,"*"&G9&"*")
A10: powdery | B10: 파우더리 | C10: 8 | D10: 아이리스·바이올렛 | E10: =COUNTIF(perfumes!$K$2:$K$200,A10) | G10: elegant | H10: 우아한 | I10: =COUNTIF(perfumes!$M$2:$M$200,"*"&G10&"*") | K10: intensity
A11: musk | B11: 머스크·클린 | C11: 9 | D11: 비누·갓 빤 빨래·살결 | E11: =COUNTIF(perfumes!$K$2:$K$200,A11) | G11: deep | H11: 묵직한 | I11: =COUNTIF(perfumes!$M$2:$M$200,"*"&G11&"*") | K11: light | L11: 가벼움
A12: spicy | B12: 스파이시 | C12: 10 | D12: 핑크페퍼·카다멈·시나몬 | E12: =COUNTIF(perfumes!$K$2:$K$200,A12) | G12: soft | H12: 보송한 | I12: =COUNTIF(perfumes!$M$2:$M$200,"*"&G12&"*") | K12: medium | L12: 보통
A13: woody | B13: 우디 | C13: 11 | D13: 시더·샌달우드·베티버 | E13: =COUNTIF(perfumes!$K$2:$K$200,A13) | G13: lovely | H13: 사랑스러운 | I13: =COUNTIF(perfumes!$M$2:$M$200,"*"&G13&"*") | K13: strong | L13: 진함
A14: amber | B14: 앰버 | C14: 12 | D14: 앰버·레진 | E14: =COUNTIF(perfumes!$K$2:$K$200,A14) | G14: sensual | H14: 매혹적인 | I14: =COUNTIF(perfumes!$M$2:$M$200,"*"&G14&"*")
A15: gourmand | B15: 구르망 | C15: 13 | D15: 바닐라·카라멜·꿀 | E15: =COUNTIF(perfumes!$K$2:$K$200,A15) | K15: polarizing
A16: leather | B16: 레더·스모키 | C16: 14 | D16: 가죽·타바코·인센스 | E16: =COUNTIF(perfumes!$K$2:$K$200,A16) | K16: low | L16: 호불호 적음
A17: 합계 | E17: =SUM(E3:E16) | K17: mid | L17: 보통
K18: high | L18: 호불호 있음
